<?xml version="1.0" ?>
<robot name="coba2" xmlns:xacro="http://ros.org/wiki/xacro">

  <link name="base_footprint"/>
  
  <joint name="base_joint" type="fixed">
    <parent link="base_footprint"/>
    <child link="base_link"/>
    <origin xyz="0.0 0.0 0.12" rpy="0 0 0"/>
  </joint>
  
  <link
    name="base_link">
    <inertial>
      <origin
        xyz="-0.0060166762532463 8.9129940104581E-08 2.0"
        rpy="0 0 0" />
      <mass
        value="45.3758520944155" />
      <inertia
        ixx="0.744970811759371"
        ixy="1.05348354286451E-06"
        ixz="0.0101713592661191"
        iyy="1.29692340687596"
        iyz="-4.79450564512486E-07"
        izz="1.6330706670946" />
    </inertial>
    <visual>
      <origin
        xyz="0 0 0"
        rpy="0 0 0" />
      <geometry>
        <mesh
          filename="package://coba2/meshes/base_link.STL" />
      </geometry>
      <material
        name="">
        <color
          rgba="0.1 0.5 0.9 1" />
      </material>
    </visual>
    <collision>
      <origin
        xyz="0 0 0"
        rpy="0 0 0" />
      <geometry>
        <mesh
          filename="package://coba2/meshes/base_link.STL" />
      </geometry>
    </collision>
  </link>
  
  <link
    name="front_wl">
    <inertial>
      <origin
        xyz="0.1625 0.178772924632851 0.0279999999999998"
        rpy="0 0 0" />
      <mass
        value="0.116774645151429" />
      <inertia
        ixx="2.21422284339803E-05"
        ixy="1.13148372324122E-17"
        ixz="3.03499487920987E-18"
        iyy="2.68140883577402E-05"
        iyz="-1.00838642356266E-17"
        izz="2.21422284339789E-05" />
    </inertial>
    <visual>
      <origin
        xyz="0 0 0"
        rpy="0 0 0" />
      <geometry>
        <mesh
          filename="package://coba2/meshes/front_wl.STL" />
      </geometry>
      <material
        name="">
        <color
          rgba="0.752941176470588 0.752941176470588 0.752941176470588 1" />
      </material>
    </visual>
    <collision>
      <origin
        xyz="0 0 0"
        rpy="0 0 0" />
      <geometry>
        <mesh
          filename="package://coba2/meshes/front_wl.STL" />
      </geometry>
    </collision>
  </link>
  
  <joint
    name="front_jl"
    type="revolute">
    <origin
      xyz="0 0 0"
      rpy="0 0 0" />
    <parent
      link="base_link" />
    <child
      link="front_wl" />
    <axis
      xyz="0 1 0" />
    <limit
      lower="0"
      upper="0"
      effort="0"
      velocity="0" />
  </joint>
  <link
    name="rear_wl">
    <inertial>
      <origin
        xyz="-0.162500000000001 0.178772924632625 0.0279999999999995"
        rpy="0 0 0" />
      <mass
        value="0.116774645154449" />
      <inertia
        ixx="2.214222843399E-05"
        ixy="-1.27081340006431E-17"
        ixz="8.52717203176794E-19"
        iyy="2.68140883577964E-05"
        iyz="1.16128439825719E-17"
        izz="2.21422284339904E-05" />
    </inertial>
    <visual>
      <origin
        xyz="0 0 0"
        rpy="0 0 0" />
      <geometry>
        <mesh
          filename="package://coba2/meshes/rear_wl.STL" />
      </geometry>
      <material
        name="">
        <color
          rgba="0.752941176470588 0.752941176470588 0.752941176470588 1" />
      </material>
    </visual>
    <collision>
      <origin
        xyz="0 0 0"
        rpy="0 0 0" />
      <geometry>
        <mesh
          filename="package://coba2/meshes/rear_wl.STL" />
      </geometry>
    </collision>
  </link>
  <joint
    name="rear_jl"
    type="revolute">
    <origin
      xyz="0 0 0"
      rpy="0 0 0" />
    <parent
      link="base_link" />
    <child
      link="rear_wl" />
    <axis
      xyz="0 1 0" />
    <limit
      lower="0"
      upper="0"
      effort="0"
      velocity="0" />
  </joint>
  <link
    name="front_wr">
    <inertial>
      <origin
        xyz="0.162499999999999 -0.178772924632877 0.0280000000000004"
        rpy="0 0 0" />
      <mass
        value="0.11677464515092" />
      <inertia
        ixx="2.21422284340529E-05"
        ixy="-6.36290159945635E-18"
        ixz="1.2516007293006E-18"
        iyy="2.68140883578077E-05"
        iyz="-1.8645494860417E-18"
        izz="2.21422284340375E-05" />
    </inertial>
    <visual>
      <origin
        xyz="0 0 0"
        rpy="0 0 0" />
      <geometry>
        <mesh
          filename="package://coba2/meshes/front_wr.STL" />
      </geometry>
      <material
        name="">
        <color
          rgba="0.752941176470588 0.752941176470588 0.752941176470588 1" />
      </material>
    </visual>
    <collision>
      <origin
        xyz="0 0 0"
        rpy="0 0 0" />
      <geometry>
        <mesh
          filename="package://coba2/meshes/front_wr.STL" />
      </geometry>
    </collision>
  </link>
  <joint
    name="front_jr"
    type="continuous">
    <origin
      xyz="0 0 0"
      rpy="0 0 0" />
    <parent
      link="base_link" />
    <child
      link="front_wr" />
    <axis
      xyz="0 -1 0" />
  </joint>
  <link
    name="rear_wr">
    <inertial>
      <origin
        xyz="-0.162499999999999 -0.178772924632694 0.0279999999999998"
        rpy="0 0 0" />
      <mass
        value="0.11677464515355" />
      <inertia
        ixx="2.2142228433999E-05"
        ixy="-1.09407353588938E-17"
        ixz="4.62190897977814E-18"
        iyy="2.68140883577919E-05"
        iyz="-1.20249595873749E-17"
        izz="2.21422284339989E-05" />
    </inertial>
    <visual>
      <origin
        xyz="0 0 0"
        rpy="0 0 0" />
      <geometry>
        <mesh
          filename="package://coba2/meshes/rear_wr.STL" />
      </geometry>
      <material
        name="">
        <color
          rgba="0.752941176470588 0.752941176470588 0.752941176470588 1" />
      </material>
    </visual>
    <collision>
      <origin
        xyz="0 0 0"
        rpy="0 0 0" />
      <geometry>
        <mesh
          filename="package://coba2/meshes/rear_wr.STL" />
      </geometry>
    </collision>
  </link>
  <joint
    name="rear_jr"
    type="revolute">
    <origin
      xyz="0 0 0"
      rpy="0 0 0" />
    <parent
      link="base_link" />
    <child
      link="rear_wr" />
    <axis
      xyz="0 -1 0" />
    <limit
      lower="0"
      upper="0"
      effort="30"
      velocity="30" />
  </joint>

  <joint name="scan_joint" type="fixed">
    <parent link="base_link"/>
    <child link="base_laser"/>
    <origin xyz="0.26 0 0.15" rpy="0 0 0"/>
  </joint>

  <link
    name="base_laser">
    <inertial>
      <origin
        xyz="-0.00029774 0.0066667 0.00013047"
        rpy="0 0 0" />
      <mass
        value="0.15717" />
      <inertia
        ixx="6.7885E-05"
        ixy="-1.3987E-07"
        ixz="-8.1554E-07"
        iyy="0.00013173"
        iyz="-9.0932E-08"
        izz="7.1972E-05" />
    </inertial>
    <visual>
      <origin
        xyz="0 0 0"
        rpy="0 0 0" />
      <geometry>
        <mesh
          filename="package://coba2/meshes/ydlidar.dae" />
      </geometry>
      <material
        name="">
        <color
          rgba="0.5 0.5 0.5 1" />
      </material>
    </visual>
    <collision>
      <origin
        xyz="0 0 0"
        rpy="0 0 0" />
      <geometry>
        <mesh
          filename="package://coba2/meshes/ydlidar.dae" />
      </geometry>
    </collision>
  </link>
</robot>
