<?xml version="1.0" encoding="utf-8"?>
<!-- This URDF was automatically created by SolidWorks to URDF Exporter! Originally created by Stephen Brawner (brawner@gmail.com) 
     Commit Version: 1.6.0-4-g7f85cfe  Build Version: 1.6.7995.38578
     For more information, please see http://wiki.ros.org/sw_urdf_exporter -->
<robot
  name="coba1">
  <link
    name="base_link">
    <inertial>
      <origin
        xyz="-0.0060166762532463 8.91299401066717E-08 0.12807893088727"
        rpy="0 0 0" />
      <mass
        value="45.3758520944155" />
      <inertia
        ixx="0.744970811759371"
        ixy="1.05348354285782E-06"
        ixz="0.0101713592661191"
        iyy="1.29692340687596"
        iyz="-4.79450564512595E-07"
        izz="1.6330706670946" />
    </inertial>
    <visual>
      <origin
        xyz="0 0 0"
        rpy="0 0 0" />
      <geometry>
        <mesh
          filename="package://coba1/meshes/base_link.STL" />
      </geometry>
      <material
        name="">
        <color
          rgba="0.792156862745098 0.819607843137255 0.933333333333333 1" />
      </material>
    </visual>
    <collision>
      <origin
        xyz="0 0 0"
        rpy="0 0 0" />
      <geometry>
        <mesh
          filename="package://coba1/meshes/base_link.STL" />
      </geometry>
    </collision>
  </link>
  <link
    name="front_wl">
    <inertial>
      <origin
        xyz="0.1625 0.178772924632851 0.0279999999999998"
        rpy="0 0 0" />
      <mass
        value="0.116774645151429" />
      <inertia
        ixx="2.21422284339803E-05"
        ixy="1.13149431115306E-17"
        ixz="3.03507428854868E-18"
        iyy="2.68140883577402E-05"
        iyz="-1.00838443768295E-17"
        izz="2.21422284339788E-05" />
    </inertial>
    <visual>
      <origin
        xyz="0 0 0"
        rpy="0 0 0" />
      <geometry>
        <mesh
          filename="package://coba1/meshes/front_wl.STL" />
      </geometry>
      <material
        name="">
        <color
          rgba="0.752941176470588 0.752941176470588 0.752941176470588 1" />
      </material>
    </visual>
    <collision>
      <origin
        xyz="0 0 0"
        rpy="0 0 0" />
      <geometry>
        <mesh
          filename="package://coba1/meshes/front_wl.STL" />
      </geometry>
    </collision>
  </link>
  <joint
    name="front_jl"
    type="revolute">
    <origin
      xyz="0 0 0"
      rpy="0 0 0" />
    <parent
      link="base_link" />
    <child
      link="front_wl" />
    <axis
      xyz="0 -1 0" />
    <limit
      lower="0"
      upper="0"
      effort="0"
      velocity="0" />
  </joint>
  <link
    name="rear_wl">
    <inertial>
      <origin
        xyz="-0.162500000000001 0.178772924632625 0.0279999999999995"
        rpy="0 0 0" />
      <mass
        value="0.116774645154449" />
      <inertia
        ixx="2.214222843399E-05"
        ixy="-1.27081472872317E-17"
        ixz="8.52763564065188E-19"
        iyy="2.68140883577964E-05"
        iyz="1.16128704588138E-17"
        izz="2.21422284339904E-05" />
    </inertial>
    <visual>
      <origin
        xyz="0 0 0"
        rpy="0 0 0" />
      <geometry>
        <mesh
          filename="package://coba1/meshes/rear_wl.STL" />
      </geometry>
      <material
        name="">
        <color
          rgba="0.752941176470588 0.752941176470588 0.752941176470588 1" />
      </material>
    </visual>
    <collision>
      <origin
        xyz="0 0 0"
        rpy="0 0 0" />
      <geometry>
        <mesh
          filename="package://coba1/meshes/rear_wl.STL" />
      </geometry>
    </collision>
  </link>
  <joint
    name="rear_jl"
    type="revolute">
    <origin
      xyz="0 0 0"
      rpy="0 0 0" />
    <parent
      link="base_link" />
    <child
      link="rear_wl" />
    <axis
      xyz="0 -1 0" />
    <limit
      lower="0"
      upper="0"
      effort="0"
      velocity="0" />
  </joint>
  <link
    name="front_wr">
    <inertial>
      <origin
        xyz="0.162499999999999 -0.178772924632877 0.0280000000000004"
        rpy="0 0 0" />
      <mass
        value="0.11677464515092" />
      <inertia
        ixx="2.21422284340529E-05"
        ixy="-6.36302071346456E-18"
        ixz="1.25172640905492E-18"
        iyy="2.68140883578077E-05"
        iyz="-1.86466861297461E-18"
        izz="2.21422284340375E-05" />
    </inertial>
    <visual>
      <origin
        xyz="0 0 0"
        rpy="0 0 0" />
      <geometry>
        <mesh
          filename="package://coba1/meshes/front_wr.STL" />
      </geometry>
      <material
        name="">
        <color
          rgba="0.752941176470588 0.752941176470588 0.752941176470588 1" />
      </material>
    </visual>
    <collision>
      <origin
        xyz="0 0 0"
        rpy="0 0 0" />
      <geometry>
        <mesh
          filename="package://coba1/meshes/front_wr.STL" />
      </geometry>
    </collision>
  </link>
  <joint
    name="front_jr"
    type="continuous">
    <origin
      xyz="0 0 0"
      rpy="0 0 0" />
    <parent
      link="base_link" />
    <child
      link="front_wr" />
    <axis
      xyz="0 1 0" />
  </joint>
  <link
    name="rear_wr">
    <inertial>
      <origin
        xyz="-0.162499999999999 -0.178772924632694 0.0279999999999998"
        rpy="0 0 0" />
      <mass
        value="0.11677464515355" />
      <inertia
        ixx="2.2142228433999E-05"
        ixy="-1.09406161802622E-17"
        ixz="4.62216704074221E-18"
        iyy="2.68140883577919E-05"
        iyz="-1.20250257618239E-17"
        izz="2.21422284339989E-05" />
    </inertial>
    <visual>
      <origin
        xyz="0 0 0"
        rpy="0 0 0" />
      <geometry>
        <mesh
          filename="package://coba1/meshes/rear_wr.STL" />
      </geometry>
      <material
        name="">
        <color
          rgba="0.752941176470588 0.752941176470588 0.752941176470588 1" />
      </material>
    </visual>
    <collision>
      <origin
        xyz="0 0 0"
        rpy="0 0 0" />
      <geometry>
        <mesh
          filename="package://coba1/meshes/rear_wr.STL" />
      </geometry>
    </collision>
  </link>
  <joint
    name="rear_jr"
    type="revolute">
    <origin
      xyz="0 0 0"
      rpy="0 0 0" />
    <parent
      link="base_link" />
    <child
      link="rear_wr" />
    <axis
      xyz="0 1 0" />
    <limit
      lower="0"
      upper="0"
      effort="30"
      velocity="30" />
  </joint>
</robot>